Traceback (most recent call last):
  File "D:\Python\backend\.\database.py", line 442, in modify_password
    cursor.execute(sql, [modified_password, username])
  File "d:\tools\anaconda\envs\cam\lib\site-packages\pymysql\cursors.py", line 148, in execute
    result = self._query(query)
  File "d:\tools\anaconda\envs\cam\lib\site-packages\pymysql\cursors.py", line 310, in _query
    conn.query(q)
  File "d:\tools\anaconda\envs\cam\lib\site-packages\pymysql\connections.py", line 548, in query
    self._affected_rows = self._read_query_result(unbuffered=unbuffered)
  File "d:\tools\anaconda\envs\cam\lib\site-packages\pymysql\connections.py", line 775, in _read_query_result
    result.read()
  File "d:\tools\anaconda\envs\cam\lib\site-packages\pymysql\connections.py", line 1156, in read
    first_packet = self.connection._read_packet()
  File "d:\tools\anaconda\envs\cam\lib\site-packages\pymysql\connections.py", line 725, in _read_packet
    packet.raise_for_error()
  File "d:\tools\anaconda\envs\cam\lib\site-packages\pymysql\protocol.py", line 221, in raise_for_error
    err.raise_mysql_exception(self._data)
  File "d:\tools\anaconda\envs\cam\lib\site-packages\pymysql\err.py", line 143, in raise_mysql_exception
    raise errorclass(errno, errval)
pymysql.err.IntegrityError: (1048, "Column 'password' cannot be null")
Traceback (most recent call last):
  File "D:\Python\backend\.\database.py", line 443, in modify_password
    cursor.execute(sql, [modified_password, username])
  File "d:\tools\anaconda\envs\cam\lib\site-packages\pymysql\cursors.py", line 148, in execute
    result = self._query(query)
  File "d:\tools\anaconda\envs\cam\lib\site-packages\pymysql\cursors.py", line 310, in _query
    conn.query(q)
  File "d:\tools\anaconda\envs\cam\lib\site-packages\pymysql\connections.py", line 548, in query
    self._affected_rows = self._read_query_result(unbuffered=unbuffered)
  File "d:\tools\anaconda\envs\cam\lib\site-packages\pymysql\connections.py", line 775, in _read_query_result
    result.read()
  File "d:\tools\anaconda\envs\cam\lib\site-packages\pymysql\connections.py", line 1156, in read
    first_packet = self.connection._read_packet()
  File "d:\tools\anaconda\envs\cam\lib\site-packages\pymysql\connections.py", line 725, in _read_packet
    packet.raise_for_error()
  File "d:\tools\anaconda\envs\cam\lib\site-packages\pymysql\protocol.py", line 221, in raise_for_error
    err.raise_mysql_exception(self._data)
  File "d:\tools\anaconda\envs\cam\lib\site-packages\pymysql\err.py", line 143, in raise_mysql_exception
    raise errorclass(errno, errval)
pymysql.err.IntegrityError: (1048, "Column 'password' cannot be null")
Traceback (most recent call last):
  File "D:\Python\backend\.\database.py", line 709, in delete_cam
    cursor.execute(sql)
  File "d:\tools\anaconda\envs\cam\lib\site-packages\pymysql\cursors.py", line 148, in execute
    result = self._query(query)
  File "d:\tools\anaconda\envs\cam\lib\site-packages\pymysql\cursors.py", line 310, in _query
    conn.query(q)
  File "d:\tools\anaconda\envs\cam\lib\site-packages\pymysql\connections.py", line 548, in query
    self._affected_rows = self._read_query_result(unbuffered=unbuffered)
  File "d:\tools\anaconda\envs\cam\lib\site-packages\pymysql\connections.py", line 775, in _read_query_result
    result.read()
  File "d:\tools\anaconda\envs\cam\lib\site-packages\pymysql\connections.py", line 1156, in read
    first_packet = self.connection._read_packet()
  File "d:\tools\anaconda\envs\cam\lib\site-packages\pymysql\connections.py", line 725, in _read_packet
    packet.raise_for_error()
  File "d:\tools\anaconda\envs\cam\lib\site-packages\pymysql\protocol.py", line 221, in raise_for_error
    err.raise_mysql_exception(self._data)
  File "d:\tools\anaconda\envs\cam\lib\site-packages\pymysql\err.py", line 143, in raise_mysql_exception
    raise errorclass(errno, errval)
pymysql.err.ProgrammingError: (1064, 'You have an error in your SQL syntax; check the manual that corresponds to your MySQL server version for the right syntax to use near \'* from logs where cid="1" and id="139"\' at line 1')
Traceback (most recent call last):
  File "D:\Python\backend\.\database.py", line 709, in delete_cam
    cursor.execute(sql)
  File "d:\tools\anaconda\envs\cam\lib\site-packages\pymysql\cursors.py", line 148, in execute
    result = self._query(query)
  File "d:\tools\anaconda\envs\cam\lib\site-packages\pymysql\cursors.py", line 310, in _query
    conn.query(q)
  File "d:\tools\anaconda\envs\cam\lib\site-packages\pymysql\connections.py", line 548, in query
    self._affected_rows = self._read_query_result(unbuffered=unbuffered)
  File "d:\tools\anaconda\envs\cam\lib\site-packages\pymysql\connections.py", line 775, in _read_query_result
    result.read()
  File "d:\tools\anaconda\envs\cam\lib\site-packages\pymysql\connections.py", line 1156, in read
    first_packet = self.connection._read_packet()
  File "d:\tools\anaconda\envs\cam\lib\site-packages\pymysql\connections.py", line 725, in _read_packet
    packet.raise_for_error()
  File "d:\tools\anaconda\envs\cam\lib\site-packages\pymysql\protocol.py", line 221, in raise_for_error
    err.raise_mysql_exception(self._data)
  File "d:\tools\anaconda\envs\cam\lib\site-packages\pymysql\err.py", line 143, in raise_mysql_exception
    raise errorclass(errno, errval)
pymysql.err.ProgrammingError: (1064, 'You have an error in your SQL syntax; check the manual that corresponds to your MySQL server version for the right syntax to use near \'* from logs where cid="1" and id="139"\' at line 1')
Traceback (most recent call last):
  File "D:\Python\backend\.\database.py", line 709, in delete_cam
    cursor.execute(sql)
  File "d:\tools\anaconda\envs\cam\lib\site-packages\pymysql\cursors.py", line 148, in execute
    result = self._query(query)
  File "d:\tools\anaconda\envs\cam\lib\site-packages\pymysql\cursors.py", line 310, in _query
    conn.query(q)
  File "d:\tools\anaconda\envs\cam\lib\site-packages\pymysql\connections.py", line 548, in query
    self._affected_rows = self._read_query_result(unbuffered=unbuffered)
  File "d:\tools\anaconda\envs\cam\lib\site-packages\pymysql\connections.py", line 775, in _read_query_result
    result.read()
  File "d:\tools\anaconda\envs\cam\lib\site-packages\pymysql\connections.py", line 1156, in read
    first_packet = self.connection._read_packet()
  File "d:\tools\anaconda\envs\cam\lib\site-packages\pymysql\connections.py", line 725, in _read_packet
    packet.raise_for_error()
  File "d:\tools\anaconda\envs\cam\lib\site-packages\pymysql\protocol.py", line 221, in raise_for_error
    err.raise_mysql_exception(self._data)
  File "d:\tools\anaconda\envs\cam\lib\site-packages\pymysql\err.py", line 143, in raise_mysql_exception
    raise errorclass(errno, errval)
pymysql.err.ProgrammingError: (1064, "You have an error in your SQL syntax; check the manual that corresponds to your MySQL server version for the right syntax to use near '* from logs where cid=1 and id=139' at line 1")
Traceback (most recent call last):
  File "D:\Python\backend\.\database.py", line 713, in delete_cam
    cursor.execute(sql)
  File "d:\tools\anaconda\envs\cam\lib\site-packages\pymysql\cursors.py", line 148, in execute
    result = self._query(query)
  File "d:\tools\anaconda\envs\cam\lib\site-packages\pymysql\cursors.py", line 310, in _query
    conn.query(q)
  File "d:\tools\anaconda\envs\cam\lib\site-packages\pymysql\connections.py", line 548, in query
    self._affected_rows = self._read_query_result(unbuffered=unbuffered)
  File "d:\tools\anaconda\envs\cam\lib\site-packages\pymysql\connections.py", line 775, in _read_query_result
    result.read()
  File "d:\tools\anaconda\envs\cam\lib\site-packages\pymysql\connections.py", line 1156, in read
    first_packet = self.connection._read_packet()
  File "d:\tools\anaconda\envs\cam\lib\site-packages\pymysql\connections.py", line 725, in _read_packet
    packet.raise_for_error()
  File "d:\tools\anaconda\envs\cam\lib\site-packages\pymysql\protocol.py", line 221, in raise_for_error
    err.raise_mysql_exception(self._data)
  File "d:\tools\anaconda\envs\cam\lib\site-packages\pymysql\err.py", line 143, in raise_mysql_exception
    raise errorclass(errno, errval)
pymysql.err.IntegrityError: (1451, 'Cannot delete or update a parent row: a foreign key constraint fails (`CAMotion`.`logs`, CONSTRAINT `logs_cams_id_fk` FOREIGN KEY (`cid`) REFERENCES `cams` (`id`))')
Traceback (most recent call last):
  File "D:\Python\backend\.\database.py", line 879, in buy_vip
    cursor.execute(sql, [1, uid])
  File "d:\tools\anaconda\envs\cam\lib\site-packages\pymysql\cursors.py", line 143, in execute
    while self.nextset():
  File "d:\tools\anaconda\envs\cam\lib\site-packages\pymysql\cursors.py", line 96, in nextset
    return self._nextset(False)
  File "d:\tools\anaconda\envs\cam\lib\site-packages\pymysql\cursors.py", line 83, in _nextset
    conn = self._get_db()
  File "d:\tools\anaconda\envs\cam\lib\site-packages\pymysql\cursors.py", line 65, in _get_db
    raise err.ProgrammingError("Cursor closed")
pymysql.err.ProgrammingError: Cursor closed
Traceback (most recent call last):
  File ".\database.py", line 1085, in done_report
    cursor.execute(sql)
  File "c:\users\lenovo\appdata\local\programs\python\python39\lib\site-packages\pymysql\cursors.py", line 148, in execute
    result = self._query(query)
  File "c:\users\lenovo\appdata\local\programs\python\python39\lib\site-packages\pymysql\cursors.py", line 310, in _query
    conn.query(q)
  File "c:\users\lenovo\appdata\local\programs\python\python39\lib\site-packages\pymysql\connections.py", line 548, in query
    self._affected_rows = self._read_query_result(unbuffered=unbuffered)
  File "c:\users\lenovo\appdata\local\programs\python\python39\lib\site-packages\pymysql\connections.py", line 775, in _read_query_result
    result.read()
  File "c:\users\lenovo\appdata\local\programs\python\python39\lib\site-packages\pymysql\connections.py", line 1156, in read
    first_packet = self.connection._read_packet()
  File "c:\users\lenovo\appdata\local\programs\python\python39\lib\site-packages\pymysql\connections.py", line 725, in _read_packet
    packet.raise_for_error()
  File "c:\users\lenovo\appdata\local\programs\python\python39\lib\site-packages\pymysql\protocol.py", line 221, in raise_for_error
    err.raise_mysql_exception(self._data)
  File "c:\users\lenovo\appdata\local\programs\python\python39\lib\site-packages\pymysql\err.py", line 143, in raise_mysql_exception
    raise errorclass(errno, errval)
pymysql.err.ProgrammingError: (1146, "Table 'CAMotion.reports' doesn't exist")
Traceback (most recent call last):
  File ".\database.py", line 1085, in done_report
    cursor.execute(sql)
  File "c:\users\lenovo\appdata\local\programs\python\python39\lib\site-packages\pymysql\cursors.py", line 148, in execute
    result = self._query(query)
  File "c:\users\lenovo\appdata\local\programs\python\python39\lib\site-packages\pymysql\cursors.py", line 310, in _query
    conn.query(q)
  File "c:\users\lenovo\appdata\local\programs\python\python39\lib\site-packages\pymysql\connections.py", line 548, in query
    self._affected_rows = self._read_query_result(unbuffered=unbuffered)
  File "c:\users\lenovo\appdata\local\programs\python\python39\lib\site-packages\pymysql\connections.py", line 775, in _read_query_result
    result.read()
  File "c:\users\lenovo\appdata\local\programs\python\python39\lib\site-packages\pymysql\connections.py", line 1156, in read
    first_packet = self.connection._read_packet()
  File "c:\users\lenovo\appdata\local\programs\python\python39\lib\site-packages\pymysql\connections.py", line 725, in _read_packet
    packet.raise_for_error()
  File "c:\users\lenovo\appdata\local\programs\python\python39\lib\site-packages\pymysql\protocol.py", line 221, in raise_for_error
    err.raise_mysql_exception(self._data)
  File "c:\users\lenovo\appdata\local\programs\python\python39\lib\site-packages\pymysql\err.py", line 143, in raise_mysql_exception
    raise errorclass(errno, errval)
pymysql.err.ProgrammingError: (1146, "Table 'CAMotion.reports' doesn't exist")
Traceback (most recent call last):
  File ".\database.py", line 1085, in done_report
    cursor.execute(sql)
  File "c:\users\lenovo\appdata\local\programs\python\python39\lib\site-packages\pymysql\cursors.py", line 148, in execute
    result = self._query(query)
  File "c:\users\lenovo\appdata\local\programs\python\python39\lib\site-packages\pymysql\cursors.py", line 310, in _query
    conn.query(q)
  File "c:\users\lenovo\appdata\local\programs\python\python39\lib\site-packages\pymysql\connections.py", line 548, in query
    self._affected_rows = self._read_query_result(unbuffered=unbuffered)
  File "c:\users\lenovo\appdata\local\programs\python\python39\lib\site-packages\pymysql\connections.py", line 775, in _read_query_result
    result.read()
  File "c:\users\lenovo\appdata\local\programs\python\python39\lib\site-packages\pymysql\connections.py", line 1156, in read
    first_packet = self.connection._read_packet()
  File "c:\users\lenovo\appdata\local\programs\python\python39\lib\site-packages\pymysql\connections.py", line 725, in _read_packet
    packet.raise_for_error()
  File "c:\users\lenovo\appdata\local\programs\python\python39\lib\site-packages\pymysql\protocol.py", line 221, in raise_for_error
    err.raise_mysql_exception(self._data)
  File "c:\users\lenovo\appdata\local\programs\python\python39\lib\site-packages\pymysql\err.py", line 143, in raise_mysql_exception
    raise errorclass(errno, errval)
pymysql.err.ProgrammingError: (1146, "Table 'CAMotion.reports' doesn't exist")
Traceback (most recent call last):
  File ".\database.py", line 1085, in change_report_status
    cursor.execute(sql)
  File "c:\users\lenovo\appdata\local\programs\python\python39\lib\site-packages\pymysql\cursors.py", line 148, in execute
    result = self._query(query)
  File "c:\users\lenovo\appdata\local\programs\python\python39\lib\site-packages\pymysql\cursors.py", line 310, in _query
    conn.query(q)
  File "c:\users\lenovo\appdata\local\programs\python\python39\lib\site-packages\pymysql\connections.py", line 548, in query
    self._affected_rows = self._read_query_result(unbuffered=unbuffered)
  File "c:\users\lenovo\appdata\local\programs\python\python39\lib\site-packages\pymysql\connections.py", line 775, in _read_query_result
    result.read()
  File "c:\users\lenovo\appdata\local\programs\python\python39\lib\site-packages\pymysql\connections.py", line 1156, in read
    first_packet = self.connection._read_packet()
  File "c:\users\lenovo\appdata\local\programs\python\python39\lib\site-packages\pymysql\connections.py", line 725, in _read_packet
    packet.raise_for_error()
  File "c:\users\lenovo\appdata\local\programs\python\python39\lib\site-packages\pymysql\protocol.py", line 221, in raise_for_error
    err.raise_mysql_exception(self._data)
  File "c:\users\lenovo\appdata\local\programs\python\python39\lib\site-packages\pymysql\err.py", line 143, in raise_mysql_exception
    raise errorclass(errno, errval)
pymysql.err.ProgrammingError: (1146, "Table 'CAMotion.reports' doesn't exist")
Traceback (most recent call last):
  File ".\database.py", line 1085, in change_report_status
    cursor.execute(sql)
  File "c:\users\lenovo\appdata\local\programs\python\python39\lib\site-packages\pymysql\cursors.py", line 148, in execute
    result = self._query(query)
  File "c:\users\lenovo\appdata\local\programs\python\python39\lib\site-packages\pymysql\cursors.py", line 310, in _query
    conn.query(q)
  File "c:\users\lenovo\appdata\local\programs\python\python39\lib\site-packages\pymysql\connections.py", line 548, in query
    self._affected_rows = self._read_query_result(unbuffered=unbuffered)
  File "c:\users\lenovo\appdata\local\programs\python\python39\lib\site-packages\pymysql\connections.py", line 775, in _read_query_result
    result.read()
  File "c:\users\lenovo\appdata\local\programs\python\python39\lib\site-packages\pymysql\connections.py", line 1156, in read
    first_packet = self.connection._read_packet()
  File "c:\users\lenovo\appdata\local\programs\python\python39\lib\site-packages\pymysql\connections.py", line 725, in _read_packet
    packet.raise_for_error()
  File "c:\users\lenovo\appdata\local\programs\python\python39\lib\site-packages\pymysql\protocol.py", line 221, in raise_for_error
    err.raise_mysql_exception(self._data)
  File "c:\users\lenovo\appdata\local\programs\python\python39\lib\site-packages\pymysql\err.py", line 143, in raise_mysql_exception
    raise errorclass(errno, errval)
pymysql.err.ProgrammingError: (1146, "Table 'CAMotion.reports' doesn't exist")
Traceback (most recent call last):
  File ".\database.py", line 1091, in change_report_status
    cursor.execute(sql)
  File "c:\users\lenovo\appdata\local\programs\python\python39\lib\site-packages\pymysql\cursors.py", line 143, in execute
    while self.nextset():
  File "c:\users\lenovo\appdata\local\programs\python\python39\lib\site-packages\pymysql\cursors.py", line 96, in nextset
    return self._nextset(False)
  File "c:\users\lenovo\appdata\local\programs\python\python39\lib\site-packages\pymysql\cursors.py", line 83, in _nextset
    conn = self._get_db()
  File "c:\users\lenovo\appdata\local\programs\python\python39\lib\site-packages\pymysql\cursors.py", line 65, in _get_db
    raise err.ProgrammingError("Cursor closed")
pymysql.err.ProgrammingError: Cursor closed
Traceback (most recent call last):
  File ".\database.py", line 1091, in change_report_status
    cursor.execute(sql)
  File "c:\users\lenovo\appdata\local\programs\python\python39\lib\site-packages\pymysql\cursors.py", line 143, in execute
    while self.nextset():
  File "c:\users\lenovo\appdata\local\programs\python\python39\lib\site-packages\pymysql\cursors.py", line 96, in nextset
    return self._nextset(False)
  File "c:\users\lenovo\appdata\local\programs\python\python39\lib\site-packages\pymysql\cursors.py", line 83, in _nextset
    conn = self._get_db()
  File "c:\users\lenovo\appdata\local\programs\python\python39\lib\site-packages\pymysql\cursors.py", line 65, in _get_db
    raise err.ProgrammingError("Cursor closed")
pymysql.err.ProgrammingError: Cursor closed
Traceback (most recent call last):
  File ".\database.py", line 1091, in change_report_status
    cursor.execute(sql)
  File "c:\users\lenovo\appdata\local\programs\python\python39\lib\site-packages\pymysql\cursors.py", line 143, in execute
    while self.nextset():
  File "c:\users\lenovo\appdata\local\programs\python\python39\lib\site-packages\pymysql\cursors.py", line 96, in nextset
    return self._nextset(False)
  File "c:\users\lenovo\appdata\local\programs\python\python39\lib\site-packages\pymysql\cursors.py", line 83, in _nextset
    conn = self._get_db()
  File "c:\users\lenovo\appdata\local\programs\python\python39\lib\site-packages\pymysql\cursors.py", line 65, in _get_db
    raise err.ProgrammingError("Cursor closed")
pymysql.err.ProgrammingError: Cursor closed
Traceback (most recent call last):
  File "D:\project\many\backend\.\database.py", line 1318, in get_report
    info = row[1]
IndexError: tuple index out of range
Traceback (most recent call last):
  File "D:\project\many\backend\.\database.py", line 1319, in get_report
    info = row[1]
IndexError: tuple index out of range
Traceback (most recent call last):
  File "D:\project\many\backend\.\database.py", line 1319, in get_report
    info = row[1]
IndexError: tuple index out of range
Traceback (most recent call last):
  File "D:\project\many\backend\.\database.py", line 1318, in get_report
    info = row[1]
IndexError: tuple index out of range
Traceback (most recent call last):
  File "D:\project\many\backend\.\database.py", line 1319, in get_report
    info = row[1]
IndexError: tuple index out of range
Traceback (most recent call last):
  File "D:\project\many\backend\.\database.py", line 1319, in get_report
    info = row[1]
IndexError: tuple index out of range
Traceback (most recent call last):
  File "D:\project\many\backend\.\database.py", line 1318, in get_report
    info = row[1]
IndexError: tuple index out of range
Traceback (most recent call last):
  File "D:\project\many\backend\.\database.py", line 1319, in get_report
    info = row[1]
IndexError: tuple index out of range
Traceback (most recent call last):
  File "D:\project\many\backend\.\database.py", line 1319, in get_report
    info = row[1]
IndexError: tuple index out of range
Traceback (most recent call last):
  File "D:\project\many\backend\.\database.py", line 1395, in delete_all_cam
    cursor.execute(sql)
  File "C:\Users\17928\.conda\envs\py38\lib\site-packages\pymysql\cursors.py", line 148, in execute
    result = self._query(query)
  File "C:\Users\17928\.conda\envs\py38\lib\site-packages\pymysql\cursors.py", line 310, in _query
    conn.query(q)
  File "C:\Users\17928\.conda\envs\py38\lib\site-packages\pymysql\connections.py", line 548, in query
    self._affected_rows = self._read_query_result(unbuffered=unbuffered)
  File "C:\Users\17928\.conda\envs\py38\lib\site-packages\pymysql\connections.py", line 775, in _read_query_result
    result.read()
  File "C:\Users\17928\.conda\envs\py38\lib\site-packages\pymysql\connections.py", line 1156, in read
    first_packet = self.connection._read_packet()
  File "C:\Users\17928\.conda\envs\py38\lib\site-packages\pymysql\connections.py", line 725, in _read_packet
    packet.raise_for_error()
  File "C:\Users\17928\.conda\envs\py38\lib\site-packages\pymysql\protocol.py", line 221, in raise_for_error
    err.raise_mysql_exception(self._data)
  File "C:\Users\17928\.conda\envs\py38\lib\site-packages\pymysql\err.py", line 143, in raise_mysql_exception
    raise errorclass(errno, errval)
pymysql.err.ProgrammingError: (1146, "Table 'CAMotion.camera' doesn't exist")
Traceback (most recent call last):
  File "D:\project\many\backend\.\database.py", line 1468, in get_url
    cursor.execute(sql)
  File "C:\Users\17928\.conda\envs\py38\lib\site-packages\pymysql\cursors.py", line 148, in execute
    result = self._query(query)
  File "C:\Users\17928\.conda\envs\py38\lib\site-packages\pymysql\cursors.py", line 310, in _query
    conn.query(q)
  File "C:\Users\17928\.conda\envs\py38\lib\site-packages\pymysql\connections.py", line 548, in query
    self._affected_rows = self._read_query_result(unbuffered=unbuffered)
  File "C:\Users\17928\.conda\envs\py38\lib\site-packages\pymysql\connections.py", line 775, in _read_query_result
    result.read()
  File "C:\Users\17928\.conda\envs\py38\lib\site-packages\pymysql\connections.py", line 1156, in read
    first_packet = self.connection._read_packet()
  File "C:\Users\17928\.conda\envs\py38\lib\site-packages\pymysql\connections.py", line 725, in _read_packet
    packet.raise_for_error()
  File "C:\Users\17928\.conda\envs\py38\lib\site-packages\pymysql\protocol.py", line 221, in raise_for_error
    err.raise_mysql_exception(self._data)
  File "C:\Users\17928\.conda\envs\py38\lib\site-packages\pymysql\err.py", line 143, in raise_mysql_exception
    raise errorclass(errno, errval)
pymysql.err.OperationalError: (1054, "Unknown column 'cid' in 'where clause'")
Traceback (most recent call last):
  File "D:\project\many\backend\.\database.py", line 1472, in get_url
    url = row[2]
IndexError: tuple index out of range
